Workbook

Sheet Содержание
A1: ToolKit Excel. Базовый уровень. Проект
A4: № | B4: Лист | C4: Содержимое / описание
A5: 1 | B5: Содержание
A6: 2 | B6: Задание | C6: Описание кейса и задания
A7: 3 | B7: Личные данные | C7: Информация о действующих абонентах оператора
A8: 4 | B8: Результаты опроса | C8: Результаты опроса целевой аудитории в новом регионе
A9: 5 | B9: Дополнительные данные | C9: Информация о тарифах, дополнительных услугах и вопросы анкеты

Sheet Задание
A1: ToolKit Excel. Базовый уровень. Проект
A4: Описание кейса
A6: Май 2022 года. Сотовый оператор планирует расшириться на новый регион. Вы участвуете в проведении маркетингового исследовния и должны определить, какой тариф будет пользоваться популярностью у абонентов 18-25 лет.
A9: Ваши задачи:
A10: 1. В соседних регионах с похожими соцально-экономическими условиями оператор предлагает для этой целевой аудитории тариф "Онлайн".
A11: Проанализируйте, можно ли продвигать его на тех же уловиях в новом регионе.
A12: 2. Оператор хочет предложить акцию для новых абонентов: пакет из 2 дополнительных услуг будет бесплатным первые два месяца после подключения.
A13: Определите, какие 2 услуги будут наиболее привлекательны для целевой аудитории.
A16: Алгоритм работы
A18: Шаг 1 | B18: Подготовьте личные данные пользователей
B19: 1. Вычислите, сколько в среднем в месяц абоненты звонят и используют интернет. Для удобства указывайте время в минутах, а интернет-трафик - в гигабайтах.
B20: Для упрощения введите предпосылку, что каждый месяц абоненты тратят примерно одинаковое число минут и гигабайт.
B21: Подсказка: для подсчета средних значений для новых абонентов, которые подключились в 2022 году, используйте формулу DATEDIF.
B22: 2. (По желанию) Удалите лишние данные: ненужные для анализа колонки и абонентов не из целевой аудитории (не в возрасте 18-25 лет на 01.05.2022).
B23: 3. Перенесите информацию об абонентской плате с листа "Дополнительная информация".
A25: Шаг 2 | B25: Подготовьте результаты опроса
B26: Очистите данные опроса: удалите дубли, пустые и не до конца заполненные строки и респондентов не из ЦА (не в возрасте 18-25 лет).
A28: Шаг 3 | B28: Оцените, какие параметры тарифа лучше подойдут целевой аудитории
B29: Постройте сводную таблицу, показыващую популярность возможных комбинаций минут и гигабайт среди тех, кто не доволен своим сотовым оператором.
B30: Постройте соответствующий график.
B31: Считайте, что абонент не доволен оператором, ести он не ответил "полностью удовлетворен" или "скорее удовлетворен".
A33: Шаг 4 | B33: Сравните результаты с предпочтениями абонентов из другого региона
B34: 1. Сгруппируйте данные о потраченных минутах и гигабайтах: используйте разделение из опроса.
B35: Для перевода из месяцев в недели считайте, что в 1 месяце 30 дней.
B36: 2. Постройте сводную таблицу и график, как в Шаге 3. Учитывайте только абонентов в возрасте 18-25 лет на 01.05.2022.
A38: Шаг 5 | B38: Оценить готовность платить за тариф
B39: 1. Постройте круговые диаграммы:
B40: а) распределение абонентской платы действующих абонентов;
B41: б) распределение субъективной готовости платить среди респондентов, недовольных своим оператором.
B42: 2. Определите, какой процент потенциальных клиентов в новом регионе готовы платить 330 рублей за тариф Онлайн:
B43: а) посчитайте число респондентов, которым подошёл бы тариф Онлайн.
B44: Это те респонденты, недовольные своим нынешним оператором, которые говорят по телефону меньше 35 минут в неделю и тратят меньше 40 Гб интернета в месяц;
B45: б) посчитайте, сколько из них готовы платить 250-350 рублей за подходящий тариф
A47: Шаг 6 | B47: Выберите, какие доплнительные функции лучше включить в подарочный пакет услуг
B48: Оператор планирует предложить потенциальным абонентам акцию: два месяца бесплатного использования пакета из двух дополнительных услуг.
B49: Чтобы сформировать наиболее привлекательный для ЦА пакет, постройте матрицу и определите, какая пара дополнительных услуг наиболее популярна среди абонентов.
B50: То есть, какие две услуги чаще всего подключены одновременно.

Sheet Личные данные
A1: ToolKit Excel. Базовый уровень. Проект
A2: Дата создания отчета | C2: 44682 | Q2: avg_min | R2: =AVERAGEIFS(Q6:Q1144,S6:S1144,"<=25") -> 202.35341
A3: Начало года | C3: 44562 | Q3: avg_gb | R3: =AVERAGEIFS(R6:R1144,S6:S1144,"<=25") -> 24.192337
A5: ID | B5: Дата рождения | C5: Пол | D5: Код регина | E5: Способ получения номера | F5: Тариф | G5: Дата перехода на тариф | H5: Месяцев использования тарифа с 01/01/2022 (сколько раз была списана абонентская плата) | I5: Секунд потрачено на звонки с 01/01/2022 | J5: Килобайт трафика потрачено с 01/01/2022 | K5: Подписка на онлайн-кинотеатр | L5: Подписка на электронную библиотеку | M5: Подписка на TV | N5: Подписка на онлайн-курсы | O5: Фитнес приложение | P5: Сколько дней пользуются тарифом | Q5: Потребление минут в месяц | R5: Потребление ГБ в месяц | S5: Сколько лет пользователям? | T5: Трата минут в неделю | U5: Категория минут | V5: Категория ГБ
A6: AXOBV991 | B6: 38105 | C6: женский | D6: R51 | E6: присвоение нового номера | F6: Ультра | G6: 44004 | H6: 5 | I6: 99496 | J6: 176000000 | P6: =IF(G6>$C$3,DATEDIF(G6,$C$2,"D"),DATEDIF($C$3,$C$2,"D")) -> 120 | Q6: =I6/60/P6*30 -> 414.56667 | R6: =J6/1024^2/P6*30 -> 41.96167 | S6: =DATEDIF(B6,$C$2,"Y") -> 18 | T6: =(Q6*7)/30 -> 96.732222 | U6: =IF(T6>120,"120+",IF(T6>90,"91-120",IF(T6>60,"61-90",IF(T6>35,"35-60","<35")))) -> 91-120 | V6: =IF(R6>40,"40+ Гб",IF(R6>30,"31-40 Гб",IF(R6>20,"21-30 Гб",IF(R6>10,"10-20 Гб","<10 Гб")))) -> 40+ Гб
A7: YIWQU824 | B7: 38101 | C7: мужской | D7: R51 | E7: присвоение нового номера | F7: Онлайн | G7: 43201 | H7: 5 | I7: 22176 | J7: 136000000 | K7: 1 | N7: 1 | P7: =IF(G7>$C$3,DATEDIF(G7,$C$2,"D"),DATEDIF($C$3,$C$2,"D")) -> 120 | Q7: =I7/60/P7*30 -> 92.4 | R7: =J7/1024^2/P7*30 -> 32.424927 | S7: =DATEDIF(B7,$C$2,"Y") -> 18 | T7: =(Q7*7)/30 -> 21.56 | U7: =IF(T7>120,"120+",IF(T7>90,"91-120",IF(T7>60,"61-90",IF(T7>35,"35-60","<35")))) -> <35 | V7: =IF(R7>40,"40+ Гб",IF(R7>30,"31-40 Гб",IF(R7>20,"21-30 Гб",IF(R7>10,"10-20 Гб","<10 Гб")))) -> 31-40 Гб
A8: TVVXJ702 | B8: 38086 | C8: женский | D8: R51 | E8: присвоение нового номера | F8: Онлайн | G8: 43938 | H8: 5 | I8: 4064 | J8: 152000000 | L8: 1 | N8: 1 | O8: 1 | P8: =IF(G8>$C$3,DATEDIF(G8,$C$2,"D"),DATEDIF($C$3,$C$2,"D")) -> 120 | Q8: =I8/60/P8*30 -> 16.933333 | R8: =J8/1024^2/P8*30 -> 36.239624 | S8: =DATEDIF(B8,$C$2,"Y") -> 18 | T8: =(Q8*7)/30 -> 3.9511111 | U8: =IF(T8>120,"120+",IF(T8>90,"91-120",IF(T8>60,"61-90",IF(T8>35,"35-60","<35")))) -> <35 | V8: =IF(R8>40,"40+ Гб",IF(R8>30,"31-40 Гб",IF(R8>20,"21-30 Гб",IF(R8>10,"10-20 Гб","<10 Гб")))) -> 31-40 Гб
A9: YIZKW418 | B9: 38086 | C9: женский | D9: R51 | E9: перенос существующего номера | F9: Базовый | G9: 43739 | H9: 5 | I9: 30344 | J9: 16000000 | K9: 1 | P9: =IF(G9>$C$3,DATEDIF(G9,$C$2,"D"),DATEDIF($C$3,$C$2,"D")) -> 120 | Q9: =I9/60/P9*30 -> 126.43333 | R9: =J9/1024^2/P9*30 -> 3.8146973 | S9: =DATEDIF(B9,$C$2,"Y") -> 18 | T9: =(Q9*7)/30 -> 29.501111 | U9: =IF(T9>120,"120+",IF(T9>90,"91-120",IF(T9>60,"61-90",IF(T9>35,"35-60","<35")))) -> <35 | V9: =IF(R9>40,"40+ Гб",IF(R9>30,"31-40 Гб",IF(R9>20,"21-30 Гб",IF(R9>10,"10-20 Гб","<10 Гб")))) -> <10 Гб
A10: MXYOM801 | B10: 38082 | C10: мужской | D10: R51 | E10: присвоение нового номера | F10: Онлайн | G10: 44058 | H10: 5 | I10: 6616 | J10: 144000000 | L10: 1 | O10: 1 | P10: =IF(G10>$C$3,DATEDIF(G10,$C$2,"D"),DATEDIF($C$3,$C$2,"D")) -> 120 | Q10: =I10/60/P10*30 -> 27.566667 | R10: =J10/1024^2/P10*30 -> 34.332275 | S10: =DATEDIF(B10,$C$2,"Y") -> 18 | T10: =(Q10*7)/30 -> 6.4322222 | U10: =IF(T10>120,"120+",IF(T10>90,"91-120",IF(T10>60,"61-90",IF(T10>35,"35-60","<35")))) -> <35 | V10: =IF(R10>40,"40+ Гб",IF(R10>30,"31-40 Гб",IF(R10>20,"21-30 Гб",IF(R10>10,"10-20 Гб","<10 Гб")))) -> 31-40 Гб
A11: GVTCR352 | B11: 38081 | C11: женский | D11: R51 | E11: перенос существующего номера | F11: Комфорт | G11: 43439 | H11: 5 | I11: 61756 | J11: 96000000 | P11: =IF(G11>$C$3,DATEDIF(G11,$C$2,"D"),DATEDIF($C$3,$C$2,"D")) -> 120 | Q11: =I11/60/P11*30 -> 257.31667 | R11: =J11/1024^2/P11*30 -> 22.888184 | S11: =DATEDIF(B11,$C$2,"Y") -> 18 | T11: =(Q11*7)/30 -> 60.040556 | U11: =IF(T11>120,"120+",IF(T11>90,"91-120",IF(T11>60,"61-90",IF(T11>35,"35-60","<35")))) -> 61-90 | V11: =IF(R11>40,"40+ Гб",IF(R11>30,"31-40 Гб",IF(R11>20,"21-30 Гб",IF(R11>10,"10-20 Гб","<10 Гб")))) -> 21-30 Гб
A12: LAXMN110 | B12: 38072 | C12: мужской | D12: R51 | E12: присвоение нового номера | F12: Онлайн | G12: 43053 | H12: 5 | I12: 19144 | J12: 152000000 | P12: =IF(G12>$C$3,DATEDIF(G12,$C$2,"D"),DATEDIF($C$3,$C$2,"D")) -> 120 | Q12: =I12/60/P12*30 -> 79.766667 | R12: =J12/1024^2/P12*30 -> 36.239624 | S12: =DATEDIF(B12,$C$2,"Y") -> 18 | T12: =(Q12*7)/30 -> 18.612222 | U12: =IF(T12>120,"120+",IF(T12>90,"91-120",IF(T12>60,"61-90",IF(T12>35,"35-60","<35")))) -> <35 | V12: =IF(R12>40,"40+ Гб",IF(R12>30,"31-40 Гб",IF(R12>20,"21-30 Гб",IF(R12>10,"10-20 Гб","<10 Гб")))) -> 31-40 Гб
A13: PUAAG520 | B13: 38068 | C13: мужской | D13: R51 | E13: присвоение нового номера | F13: Комфорт | G13: 42872 | H13: 5 | I13: 3368 | J13: 100000000 | L13: 1 | O13: 1 | P13: =IF(G13>$C$3,DATEDIF(G13,$C$2,"D"),DATEDIF($C$3,$C$2,"D")) -> 120 | Q13: =I13/60/P13*30 -> 14.033333 | R13: =J13/1024^2/P13*30 -> 23.841858 | S13: =DATEDIF(B13,$C$2,"Y") -> 18 | T13: =(Q13*7)/30 -> 3.2744444 | U13: =IF(T13>120,"120+",IF(T13>90,"91-120",IF(T13>60,"61-90",IF(T13>35,"35-60","<35")))) -> <35 | V13: =IF(R13>40,"40+ Гб",IF(R13>30,"31-40 Гб",IF(R13>20,"21-30 Гб",IF(R13>10,"10-20 Гб","<10 Гб")))) -> 21-30 Гб
A14: FBCVN966 | B14: 38065 | C14: мужской | D14: R51 | E14: перенос существующего номера | F14: Премиум | G14: 44432 | H14: 5 | I14: 113756 | J14: 136000000 | K14: 1 | P14: =IF(G14>$C$3,DATEDIF(G14,$C$2,"D"),DATEDIF($C$3,$C$2,"D")) -> 120 | Q14: =I14/60/P14*30 -> 473.98333 | R14: =J14/1024^2/P14*30 -> 32.424927 | S14: =DATEDIF(B14,$C$2,"Y") -> 18 | T14: =(Q14*7)/30 -> 110.59611 | U14: =IF(T14>120,"120+",IF(T14>90,"91-120",IF(T14>60,"61-90",IF(T14>35,"35-60","<35")))) -> 91-120 | V14: =IF(R14>40,"40+ Гб",IF(R14>30,"31-40 Гб",IF(R14>20,"21-30 Гб",IF(R14>10,"10-20 Гб","<10 Гб")))) -> 31-40 Гб
A15: EMVOF074 | B15: 38059 | C15: мужской | D15: R51 | E15: присвоение нового номера | F15: Премиум | G15: 43641 | H15: 5 | I15: 105680 | J15: 100000000 | P15: =IF(G15>$C$3,DATEDIF(G15,$C$2,"D"),DATEDIF($C$3,$C$2,"D")) -> 120 | Q15: =I15/60/P15*30 -> 440.33333 | R15: =J15/1024^2/P15*30 -> 23.841858 | S15: =DATEDIF(B15,$C$2,"Y") -> 18 | T15: =(Q15*7)/30 -> 102.74444 | U15: =IF(T15>120,"120+",IF(T15>90,"91-120",IF(T15>60,"61-90",IF(T15>35,"35-60","<35")))) -> 91-120 | V15: =IF(R15>40,"40+ Гб",IF(R15>30,"31-40 Гб",IF(R15>20,"21-30 Гб",IF(R15>10,"10-20 Гб","<10 Гб")))) -> 21-30 Гб | X15: Тарифные планы | AC15: Дополнительные услуги
A16: FRRVI702 | B16: 38056 | C16: женский | D16: R51 | E16: перенос существующего номера | F16: Премиум | G16: 43778 | H16: 5 | I16: 20436 | J16: 140000000 | P16: =IF(G16>$C$3,DATEDIF(G16,$C$2,"D"),DATEDIF($C$3,$C$2,"D")) -> 120 | Q16: =I16/60/P16*30 -> 85.15 | R16: =J16/1024^2/P16*30 -> 33.378601 | S16: =DATEDIF(B16,$C$2,"Y") -> 18 | T16: =(Q16*7)/30 -> 19.868333 | U16: =IF(T16>120,"120+",IF(T16>90,"91-120",IF(T16>60,"61-90",IF(T16>35,"35-60","<35")))) -> <35 | V16: =IF(R16>40,"40+ Гб",IF(R16>30,"31-40 Гб",IF(R16>20,"21-30 Гб",IF(R16>10,"10-20 Гб","<10 Гб")))) -> 31-40 Гб | X16: Тариф | Y16: Абонентская плата | Z16: Звонки | AA16: Гб | AC16: Подписка на онлайн-кинотеатр
A17: NRQRT304 | B17: 38049 | C17: мужской | D17: R51 | E17: присвоение нового номера | F17: Онлайн | G17: 44276 | H17: 5 | I17: 2840 | J17: 156000000 | L17: 1 | O17: 1 | P17: =IF(G17>$C$3,DATEDIF(G17,$C$2,"D"),DATEDIF($C$3,$C$2,"D")) -> 120 | Q17: =I17/60/P17*30 -> 11.833333 | R17: =J17/1024^2/P17*30 -> 37.193298 | S17: =DATEDIF(B17,$C$2,"Y") -> 18 | T17: =(Q17*7)/30 -> 2.7611111 | U17: =IF(T17>120,"120+",IF(T17>90,"91-120",IF(T17>60,"61-90",IF(T17>35,"35-60","<35")))) -> <35 | V17: =IF(R17>40,"40+ Гб",IF(R17>30,"31-40 Гб",IF(R17>20,"21-30 Гб",IF(R17>10,"10-20 Гб","<10 Гб")))) -> 31-40 Гб | X17: Ультра | Y17: 770 | Z17: 700 | AA17: 50 | AC17: Подписка на электронную библиотеку
A18: TPTOR701 | B18: 38049 | C18: мужской | D18: R51 | E18: перенос существующего номера | F18: Онлайн | G18: 44358 | H18: 5 | I18: 10328 | J18: 144000000 | L18: 1 | N18: 1 | O18: 1 | P18: =IF(G18>$C$3,DATEDIF(G18,$C$2,"D"),DATEDIF($C$3,$C$2,"D")) -> 120 | Q18: =I18/60/P18*30 -> 43.033333 | R18: =J18/1024^2/P18*30 -> 34.332275 | S18: =DATEDIF(B18,$C$2,"Y") -> 18 | T18: =(Q18*7)/30 -> 10.041111 | U18: =IF(T18>120,"120+",IF(T18>90,"91-120",IF(T18>60,"61-90",IF(T18>35,"35-60","<35")))) -> <35 | V18: =IF(R18>40,"40+ Гб",IF(R18>30,"31-40 Гб",IF(R18>20,"21-30 Гб",IF(R18>10,"10-20 Гб","<10 Гб")))) -> 31-40 Гб | X18: Премиум | Y18: 550 | Z18: 500 | AA18: 35 | AC18: Подписка на TV
A19: RRYYM097 | B19: 38048 | C19: женский | D19: R51 | E19: присвоение нового номера | F19: Онлайн | G19: 44070 | H19: 5 | I19: 20720 | J19: 152000000 | P19: =IF(G19>$C$3,DATEDIF(G19,$C$2,"D"),DATEDIF($C$3,$C$2,"D")) -> 120 | Q19: =I19/60/P19*30 -> 86.333333 | R19: =J19/1024^2/P19*30 -> 36.239624 | S19: =DATEDIF(B19,$C$2,"Y") -> 18 | T19: =(Q19*7)/30 -> 20.144444 | U19: =IF(T19>120,"120+",IF(T19>90,"91-120",IF(T19>60,"61-90",IF(T19>35,"35-60","<35")))) -> <35 | V19: =IF(R19>40,"40+ Гб",IF(R19>30,"31-40 Гб",IF(R19>20,"21-30 Гб",IF(R19>10,"10-20 Гб","<10 Гб")))) -> 31-40 Гб | X19: Комфорт | Y19: 440 | Z19: 400 | AA19: 30 | AC19: Подписка на онлайн-курсы
A20: IGOYU966 | B20: 38046 | C20: мужской | D20: R51 | E20: присвоение нового номера | F20: Комфорт | G20: 43614 | H20: 5 | I20: 90940 | J20: 40000000 | L20: 1 | P20: =IF(G20>$C$3,DATEDIF(G20,$C$2,"D"),DATEDIF($C$3,$C$2,"D")) -> 120 | Q20: =I20/60/P20*30 -> 378.91667 | R20: =J20/1024^2/P20*30 -> 9.5367432 | S20: =DATEDIF(B20,$C$2,"Y") -> 18 | T20: =(Q20*7)/30 -> 88.413889 | U20: =IF(T20>120,"120+",IF(T20>90,"91-120",IF(T20>60,"61-90",IF(T20>35,"35-60","<35")))) -> 61-90 | V20: =IF(R20>40,"40+ Гб",IF(R20>30,"31-40 Гб",IF(R20>20,"21-30 Гб",IF(R20>10,"10-20 Гб","<10 Гб")))) -> <10 Гб | X20: Онлайн | Y20: 330 | Z20: 150 | AA20: 40 | AC20: Фитнес приложение
A21: ZQZTD201 | B21: 38039 | C21: мужской | D21: R51 | E21: присвоение нового номера | F21: Базовый | G21: 43053 | H21: 5 | I21: 30328 | J21: 4000000 | K21: 1 | N21: 1 | P21: =IF(G21>$C$3,DATEDIF(G21,$C$2,"D"),DATEDIF($C$3,$C$2,"D")) -> 120 | Q21: =I21/60/P21*30 -> 126.36667 | R21: =J21/1024^2/P21*30 -> 0.95367432 | S21: =DATEDIF(B21,$C$2,"Y") -> 18 | T21: =(Q21*7)/30 -> 29.485556 | U21: =IF(T21>120,"120+",IF(T21>90,"91-120",IF(T21>60,"61-90",IF(T21>35,"35-60","<35")))) -> <35 | V21: =IF(R21>40,"40+ Гб",IF(R21>30,"31-40 Гб",IF(R21>20,"21-30 Гб",IF(R21>10,"10-20 Гб","<10 Гб")))) -> <10 Гб | X21: Базовый | Y21: 220 | Z21: 200 | AA21: 5
A22: SHJYU629 | B22: 38038 | C22: мужской | D22: R51 | E22: присвоение нового номера | F22: Онлайн | G22: 42768 | H22: 5 | I22: 18848 | J22: 64000000 | N22: 1 | P22: =IF(G22>$C$3,DATEDIF(G22,$C$2,"D"),DATEDIF($C$3,$C$2,"D")) -> 120 | Q22: =I22/60/P22*30 -> 78.533333 | R22: =J22/1024^2/P22*30 -> 15.258789 | S22: =DATEDIF(B22,$C$2,"Y") -> 18 | T22: =(Q22*7)/30 -> 18.324444 | U22: =IF(T22>120,"120+",IF(T22>90,"91-120",IF(T22>60,"61-90",IF(T22>35,"35-60","<35")))) -> <35 | V22: =IF(R22>40,"40+ Гб",IF(R22>30,"31-40 Гб",IF(R22>20,"21-30 Гб",IF(R22>10,"10-20 Гб","<10 Гб")))) -> 10-20 Гб
A23: FVWTK713 | B23: 38036 | C23: женский | D23: R51 | E23: присвоение нового номера | F23: Премиум | G23: 44435 | H23: 5 | I23: 100412 | J23: 72000000 | P23: =IF(G23>$C$3,DATEDIF(G23,$C$2,"D"),DATEDIF($C$3,$C$2,"D")) -> 120 | Q23: =I23/60/P23*30 -> 418.38333 | R23: =J23/1024^2/P23*30 -> 17.166138 | S23: =DATEDIF(B23,$C$2,"Y") -> 18 | T23: =(Q23*7)/30 -> 97.622778 | U23: =IF(T23>120,"120+",IF(T23>90,"91-120",IF(T23>60,"61-90",IF(T23>35,"35-60","<35")))) -> 91-120 | V23: =IF(R23>40,"40+ Гб",IF(R23>30,"31-40 Гб",IF(R23>20,"21-30 Гб",IF(R23>10,"10-20 Гб","<10 Гб")))) -> 10-20 Гб
A24: VUMJS954 | B24: 38033 | C24: женский | D24: R51 | E24: перенос существующего номера | F24: Онлайн | G24: 43568 | H24: 5 | I24: 10184 | J24: 148000000 | P24: =IF(G24>$C$3,DATEDIF(G24,$C$2,"D"),DATEDIF($C$3,$C$2,"D")) -> 120 | Q24: =I24/60/P24*30 -> 42.433333 | R24: =J24/1024^2/P24*30 -> 35.28595 | S24: =DATEDIF(B24,$C$2,"Y") -> 18 | T24: =(Q24*7)/30 -> 9.9011111 | U24: =IF(T24>120,"120+",IF(T24>90,"91-120",IF(T24>60,"61-90",IF(T24>35,"35-60","<35")))) -> <35 | V24: =IF(R24>40,"40+ Гб",IF(R24>30,"31-40 Гб",IF(R24>20,"21-30 Гб",IF(R24>10,"10-20 Гб","<10 Гб")))) -> 31-40 Гб
A25: TGNME740 | B25: 38023 | C25: женский | D25: R51 | E25: перенос существующего номера | F25: Онлайн | G25: 43528 | H25: 5 | I25: 14816 | J25: 156000000 | L25: 1 | O25: 1 | P25: =IF(G25>$C$3,DATEDIF(G25,$C$2,"D"),DATEDIF($C$3,$C$2,"D")) -> 120 | Q25: =I25/60/P25*30 -> 61.733333 | R25: =J25/1024^2/P25*30 -> 37.193298 | S25: =DATEDIF(B25,$C$2,"Y") -> 18 | T25: =(Q25*7)/30 -> 14.404444 | U25: =IF(T25>120,"120+",IF(T25>90,"91-120",IF(T25>60,"61-90",IF(T25>35,"35-60","<35")))) -> <35 | V25: =IF(R25>40,"40+ Гб",IF(R25>30,"31-40 Гб",IF(R25>20,"21-30 Гб",IF(R25>10,"10-20 Гб","<10 Гб")))) -> 31-40 Гб
A26: JSVAN850 | B26: 38020 | C26: женский | D26: R51 | E26: перенос существующего номера | F26: Онлайн | G26: 43825 | H26: 5 | I26: 21444 | J26: 152000000 | L26: 1 | N26: 1 | O26: 1 | P26: =IF(G26>$C$3,DATEDIF(G26,$C$2,"D"),DATEDIF($C$3,$C$2,"D")) -> 120 | Q26: =I26/60/P26*30 -> 89.35 | R26: =J26/1024^2/P26*30 -> 36.239624 | S26: =DATEDIF(B26,$C$2,"Y") -> 18 | T26: =(Q26*7)/30 -> 20.848333 | U26: =IF(T26>120,"120+",IF(T26>90,"91-120",IF(T26>60,"61-90",IF(T26>35,"35-60","<35")))) -> <35 | V26: =IF(R26>40,"40+ Гб",IF(R26>30,"31-40 Гб",IF(R26>20,"21-30 Гб",IF(R26>10,"10-20 Гб","<10 Гб")))) -> 31-40 Гб
A27: SJZLW931 | B27: 38018 | C27: женский | D27: R51 | E27: перенос существующего номера | F27: Онлайн | G27: 43421 | H27: 5 | I27: 14164 | J27: 148000000 | P27: =IF(G27>$C$3,DATEDIF(G27,$C$2,"D"),DATEDIF($C$3,$C$2,"D")) -> 120 | Q27: =I27/60/P27*30 -> 59.016667 | R27: =J27/1024^2/P27*30 -> 35.28595 | S27: =DATEDIF(B27,$C$2,"Y") -> 18 | T27: =(Q27*7)/30 -> 13.770556 | U27: =IF(T27>120,"120+",IF(T27>90,"91-120",IF(T27>60,"61-90",IF(T27>35,"35-60","<35")))) -> <35 | V27: =IF(R27>40,"40+ Гб",IF(R27>30,"31-40 Гб",IF(R27>20,"21-30 Гб",IF(R27>10,"10-20 Гб","<10 Гб")))) -> 31-40 Гб
A28: IPMUO011 | B28: 38015 | C28: женский | D28: R51 | E28: перенос существующего номера | F28: Онлайн | G28: 43511 | H28: 5 | I28: 12040 | J28: 156000000 | K28: 1 | N28: 1 | P28: =IF(G28>$C$3,DATEDIF(G28,$C$2,"D"),DATEDIF($C$3,$C$2,"D")) -> 120 | Q28: =I28/60/P28*30 -> 50.166667 | R28: =J28/1024^2/P28*30 -> 37.193298 | S28: =DATEDIF(B28,$C$2,"Y") -> 18 | T28: =(Q28*7)/30 -> 11.705556 | U28: =IF(T28>120,"120+",IF(T28>90,"91-120",IF(T28>60,"61-90",IF(T28>35,"35-60","<35")))) -> <35 | V28: =IF(R28>40,"40+ Гб",IF(R28>30,"31-40 Гб",IF(R28>20,"21-30 Гб",IF(R28>10,"10-20 Гб","<10 Гб")))) -> 31-40 Гб
A29: PTZQU800 | B29: 38015 | C29: мужской | D29: R51 | E29: перенос существующего номера | F29: Комфорт | G29: 43423 | H29: 5 | I29: 91856 | J29: 100000000 | M29: 1 | P29: =IF(G29>$C$3,DATEDIF(G29,$C$2,"D"),DATEDIF($C$3,$C$2,"D")) -> 120 | Q29: =I29/60/P29*30 -> 382.73333 | R29: =J29/1024^2/P29*30 -> 23.841858 | S29: =DATEDIF(B29,$C$2,"Y") -> 18 | T29: =(Q29*7)/30 -> 89.304444 | U29: =IF(T29>120,"120+",IF(T29>90,"91-120",IF(T29>60,"61-90",IF(T29>35,"35-60","<35")))) -> 61-90 | V29: =IF(R29>40,"40+ Гб",IF(R29>30,"31-40 Гб",IF(R29>20,"21-30 Гб",IF(R29>10,"10-20 Гб","<10 Гб")))) -> 21-30 Гб
A30: PMOYT654 | B30: 38014 | C30: женский | D30: R51 | E30: присвоение нового номера | F30: Онлайн | G30: 43248 | H30: 5 | I30: 10688 | J30: 160000000 | P30: =IF(G30>$C$3,DATEDIF(G30,$C$2,"D"),DATEDIF($C$3,$C$2,"D")) -> 120 | Q30: =I30/60/P30*30 -> 44.533333 | R30: =J30/1024^2/P30*30 -> 38.146973 | S30: =DATEDIF(B30,$C$2,"Y") -> 18 | T30: =(Q30*7)/30 -> 10.391111 | U30: =IF(T30>120,"120+",IF(T30>90,"91-120",IF(T30>60,"61-90",IF(T30>35,"35-60","<35")))) -> <35 | V30: =IF(R30>40,"40+ Гб",IF(R30>30,"31-40 Гб",IF(R30>20,"21-30 Гб",IF(R30>10,"10-20 Гб","<10 Гб")))) -> 31-40 Гб
A31: HDBHD377 | B31: 38008 | C31: мужской | D31: R51 | E31: присвоение нового номера | F31: Комфорт | G31: 44511 | H31: 5 | I31: 18680 | J31: 44000000 | K31: 1 | P31: =IF(G31>$C$3,DATEDIF(G31,$C$2,"D"),DATEDIF($C$3,$C$2,"D")) -> 120 | Q31: =I31/60/P31*30 -> 77.833333 | R31: =J31/1024^2/P31*30 -> 10.490417 | S31: =DATEDIF(B31,$C$2,"Y") -> 18 | T31: =(Q31*7)/30 -> 18.161111 | U31: =IF(T31>120,"120+",IF(T31>90,"91-120",IF(T31>60,"61-90",IF(T31>35,"35-60","<35")))) -> <35 | V31: =IF(R31>40,"40+ Гб",IF(R31>30,"31-40 Гб",IF(R31>20,"21-30 Гб",IF(R31>10,"10-20 Гб","<10 Гб")))) -> 10-20 Гб
A32: FZDJJ453 | B32: 38003 | C32: мужской | D32: R51 | E32: присвоение нового номера | F32: Премиум | G32: 43813 | H32: 5 | I32: 111984 | J32: 136000000 | P32: =IF(G32>$C$3,DATEDIF(G32,$C$2,"D"),DATEDIF($C$3,$C$2,"D")) -> 120 | Q32: =I32/60/P32*30 -> 466.6 | R32: =J32/1024^2/P32*30 -> 32.424927 | S32: =DATEDIF(B32,$C$2,"Y") -> 18 | T32: =(Q32*7)/30 -> 108.87333 | U32: =IF(T32>120,"120+",IF(T32>90,"91-120",IF(T32>60,"61-90",IF(T32>35,"35-60","<35")))) -> 91-120 | V32: =IF(R32>40,"40+ Гб",IF(R32>30,"31-40 Гб",IF(R32>20,"21-30 Гб",IF(R32>10,"10-20 Гб","<10 Гб")))) -> 31-40 Гб
A33: ZMVFL343 | B33: 37999 | C33: женский | D33: R51 | E33: присвоение нового номера | F33: Базовый | G33: 44574 | H33: 3 | I33: 53345 | J33: 10800000 | N33: 1 | O33: 1 | P33: =IF(G33>$C$3,DATEDIF(G33,$C$2,"D"),DATEDIF($C$3,$C$2,"D")) -> 108 | Q33: =I33/60/P33*30 -> 246.96759 | R33: =J33/1024^2/P33*30 -> 2.8610229 | S33: =DATEDIF(B33,$C$2,"Y") -> 18 | T33: =(Q33*7)/30 -> 57.625772 | U33: =IF(T33>120,"120+",IF(T33>90,"91-120",IF(T33>60,"61-90",IF(T33>35,"35-60","<35")))) -> 35-60 | V33: =IF(R33>40,"40+ Гб",IF(R33>30,"31-40 Гб",IF(R33>20,"21-30 Гб",IF(R33>10,"10-20 Гб","<10 Гб")))) -> <10 Гб
A34: RBMKX235 | B34: 37999 | C34: мужской | D34: R51 | E34: перенос существующего номера | F34: Онлайн | G34: 43271 | H34: 5 | I34: 22228 | J34: 140000000 | P34: =IF(G34>$C$3,DATEDIF(G34,$C$2,"D"),DATEDIF($C$3,$C$2,"D")) -> 120 | Q34: =I34/60/P34*30 -> 92.616667 | R34: =J34/1024^2/P34*30 -> 33.378601 | S34: =DATEDIF(B34,$C$2,"Y") -> 18 | T34: =(Q34*7)/30 -> 21.610556 | U34: =IF(T34>120,"120+",IF(T34>90,"91-120",IF(T34>60,"61-90",IF(T34>35,"35-60","<35")))) -> <35 | V34: =IF(R34>40,"40+ Гб",IF(R34>30,"31-40 Гб",IF(R34>20,"21-30 Гб",IF(R34>10,"10-20 Гб","<10 Гб")))) -> 31-40 Гб
A35: NECUE148 | B35: 37997 | C35: женский | D35: R51 | E35: присвоение нового номера | F35: Онлайн | G35: 43408 | H35: 5 | I35: 6036 | J35: 156000000 | L35: 1 | P35: =IF(G35>$C$3,DATEDIF(G35,$C$2,"D"),DATEDIF($C$3,$C$2,"D")) -> 120 | Q35: =I35/60/P35*30 -> 25.15 | R35: =J35/1024^2/P35*30 -> 37.193298 | S35: =DATEDIF(B35,$C$2,"Y") -> 18 | T35: =(Q35*7)/30 -> 5.8683333 | U35: =IF(T35>120,"120+",IF(T35>90,"91-120",IF(T35>60,"61-90",IF(T35>35,"35-60","<35")))) -> <35 | V35: =IF(R35>40,"40+ Гб",IF(R35>30,"31-40 Гб",IF(R35>20,"21-30 Гб",IF(R35>10,"10-20 Гб","<10 Гб")))) -> 31-40 Гб
A36: YTPJR660 | B36: 37995 | C36: мужской | D36: R51 | E36: присвоение нового номера | F36: Базовый | G36: 43511 | H36: 5 | I36: 15656 | J36: 4000000 | P36: =IF(G36>$C$3,DATEDIF(G36,$C$2,"D"),DATEDIF($C$3,$C$2,"D")) -> 120 | Q36: =I36/60/P36*30 -> 65.233333 | R36: =J36/1024^2/P36*30 -> 0.95367432 | S36: =DATEDIF(B36,$C$2,"Y") -> 18 | T36: =(Q36*7)/30 -> 15.221111 | U36: =IF(T36>120,"120+",IF(T36>90,"91-120",IF(T36>60,"61-90",IF(T36>35,"35-60","<35")))) -> <35 | V36: =IF(R36>40,"40+ Гб",IF(R36>30,"31-40 Гб",IF(R36>20,"21-30 Гб",IF(R36>10,"10-20 Гб","<10 Гб")))) -> <10 Гб
A37: URMMH384 | B37: 37990 | C37: женский | D37: R51 | E37: перенос существующего номера | F37: Онлайн | G37: 42835 | H37: 5 | I37: 15632 | J37: 156000000 | L37: 1 | O37: 1 | P37: =IF(G37>$C$3,DATEDIF(G37,$C$2,"D"),DATEDIF($C$3,$C$2,"D")) -> 120 | Q37: =I37/60/P37*30 -> 65.133333 | R37: =J37/1024^2/P37*30 -> 37.193298 | S37: =DATEDIF(B37,$C$2,"Y") -> 18 | T37: =(Q37*7)/30 -> 15.197778 | U37: =IF(T37>120,"120+",IF(T37>90,"91-120",IF(T37>60,"61-90",IF(T37>35,"35-60","<35")))) -> <35 | V37: =IF(R37>40,"40+ Гб",IF(R37>30,"31-40 Гб",IF(R37>20,"21-30 Гб",IF(R37>10,"10-20 Гб","<10 Гб")))) -> 31-40 Гб
A38: QMHJL247 | B38: 37988 | C38: женский | D38: R51 | E38: присвоение нового номера | F38: Онлайн | G38: 43364 | H38: 5 | I38: 12472 | J38: 160000000 | P38: =IF(G38>$C$3,DATEDIF(G38,$C$2,"D"),DATEDIF($C$3,$C$2,"D")) -> 120 | Q38: =I38/60/P38*30 -> 51.966667 | R38: =J38/1024^2/P38*30 -> 38.146973 | S38: =DATEDIF(B38,$C$2,"Y") -> 18 | T38: =(Q38*7)/30 -> 12.125556 | U38: =IF(T38>120,"120+",IF(T38>90,"91-120",IF(T38>60,"61-90",IF(T38>35,"35-60","<35")))) -> <35 | V38: =IF(R38>40,"40+ Гб",IF(R38>30,"31-40 Гб",IF(R38>20,"21-30 Гб",IF(R38>10,"10-20 Гб","<10 Гб")))) -> 31-40 Гб
A39: FZJPC224 | B39: 37986 | C39: женский | D39: R51 | E39: перенос существующего номера | F39: Премиум | G39: 43030 | H39: 5 | I39: 49956 | J39: 124000000 | P39: =IF(G39>$C$3,DATEDIF(G39,$C$2,"D"),DATEDIF($C$3,$C$2,"D")) -> 120 | Q39: =I39/60/P39*30 -> 208.15 | R39: =J39/1024^2/P39*30 -> 29.563904 | S39: =DATEDIF(B39,$C$2,"Y") -> 18 | T39: =(Q39*7)/30 -> 48.568333 | U39: =IF(T39>120,"120+",IF(T39>90,"91-120",IF(T39>60,"61-90",IF(T39>35,"35-60","<35")))) -> 35-60 | V39: =IF(R39>40,"40+ Гб",IF(R39>30,"31-40 Гб",IF(R39>20,"21-30 Гб",IF(R39>10,"10-20 Гб","<10 Гб")))) -> 21-30 Гб
A40: PZSOJ921 | B40: 37983 | C40: мужской | D40: R51 | E40: присвоение нового номера | F40: Онлайн | G40: 44548 | H40: 4 | I40: 33520 | J40: 128000000 | P40: =IF(G40>$C$3,DATEDIF(G40,$C$2,"D"),DATEDIF($C$3,$C$2,"D")) -> 120 | Q40: =I40/60/P40*30 -> 139.66667 | R40: =J40/1024^2/P40*30 -> 30.517578 | S40: =DATEDIF(B40,$C$2,"Y") -> 18 | T40: =(Q40*7)/30 -> 32.588889 | U40: =IF(T40>120,"120+",IF(T40>90,"91-120",IF(T40>60,"61-90",IF(T40>35,"35-60","<35")))) -> <35 | V40: =IF(R40>40,"40+ Гб",IF(R40>30,"31-40 Гб",IF(R40>20,"21-30 Гб",IF(R40>10,"10-20 Гб","<10 Гб")))) -> 31-40 Гб
A41: BOVIU389 | B41: 37972 | C41: мужской | D41: R51 | E41: перенос существующего номера | F41: Премиум | G41: 44468 | H41: 5 | I41: 92316 | J41: 120000000 | P41: =IF(G41>$C$3,DATEDIF(G41,$C$2,"D"),DATEDIF($C$3,$C$2,"D")) -> 120 | Q41: =I41/60/P41*30 -> 384.65 | R41: =J41/1024^2/P41*30 -> 28.610229 | S41: =DATEDIF(B41,$C$2,"Y") -> 18 | T41: =(Q41*7)/30 -> 89.751667 | U41: =IF(T41>120,"120+",IF(T41>90,"91-120",IF(T41>60,"61-90",IF(T41>35,"35-60","<35")))) -> 61-90 | V41: =IF(R41>40,"40+ Гб",IF(R41>30,"31-40 Гб",IF(R41>20,"21-30 Гб",IF(R41>10,"10-20 Гб","<10 Гб")))) -> 21-30 Гб
...

Sheet Результаты опроса
A1: ToolKit Excel. Базовый уровень. Проект
A2: Номер респондента | B2: Возраст | C2: Оцените, насколько вы довольны своим мобильным оператором? | D2: Сколько минут в неделю вы тратите на звонки? | E2: Сколько интернет трафика вы тратите в месяц с вашего мобильного устройства? | F2: Сколько вы готовы заплатить за оптимальный тариф?
A3: 1 | B3: 24 | C3: Полностью удовлетворен | D3: <35 | E3: <10 Гб | F3: 451-550
A4: 2 | B4: 21 | C4: Затрудняюсь ответить | D4: <35 | E4: <10 Гб | F4: 451-550
A5: 3 | B5: 25 | C5: Скорее удовлетворен | D5: <35 | E5: 21-30 Гб | F5: 550+ рублей
A6: 4 | B6: 23 | C6: Скорее удовлетворен | D6: <35 | E6: 40+ Гб | F6: 550+ рублей
A7: 5 | B7: 18 | C7: Полностью удовлетворен | D7: <35 | E7: <10 Гб | F7: 451-550
A8: 6 | B8: 19 | C8: Скорее удовлетворен | D8: <35 | E8: 40+ Гб | F8: до 250 рублей
A9: 7 | B9: 21 | C9: Скорее не удовлетворен | D9: <35 | E9: 21-30 Гб | F9: 451-550
A10: 8 | B10: 24 | C10: Скорее удовлетворен | D10: <35 | E10: 31-40 Гб | F10: 250-350
A11: 9 | B11: 21 | C11: Скорее не удовлетворен | D11: <35 | E11: 10-20 Гб | F11: 250-350
A12: 10 | B12: 22 | C12: Затрудняюсь ответить | D12: <35 | E12: 10-20 Гб | F12: 250-350
A13: 11 | B13: 18 | C13: Затрудняюсь ответить | D13: 91-120 | E13: 21-30 Гб | F13: 550+ рублей
A14: 12 | B14: 18 | C14: Затрудняюсь ответить | D14: 61-90 | E14: 21-30 Гб | F14: до 250 рублей
... A299: 304 | B299: 20 | C299: Затрудняюсь ответить | D299: 35-60 | E299: 21-30 Гб | F299: 250-350

Sheet Свод (Рез. опр.)
A1: Оцените, насколько вы довольны своим мобильным оператором? | B1: (Multiple Items)
A3: Count of Сколько вы готовы заплатить за оптимальный тариф? | B3: Сколько интернет трафика вы тратите в месяц с вашего мобильного устройства?
A4: Сколько минут в неделю вы тратите на звонки? | B4: <10 Гб | C4: 10-20 Гб | D4: 21-30 Гб | E4: 31-40 Гб | F4: 40+ Гб | G4: Grand Total | J4: Row Labels | K4: <10 Гб | L4: 10-20 Гб | M4: 21-30 Гб | N4: 31-40 Гб | O4: 40+ Гб | P4: Grand Total
A5: 91-120 | B5: 4 | C5: 3 | D5: 6 | E5: 2 | F5: 3 | G5: 18 | J5: 91-120 | K5: 4 | L5: 3 | M5: 6 | N5: 2 | O5: 3 | P5: 18
A6: 61-90 | B6: 2 | C6: 1 | D6: 9 | E6: 5 | F6: 3 | G6: 20 | J6: 61-90 | K6: 2 | L6: 1 | M6: 9 | N6: 5 | O6: 3 | P6: 20
A7: 35-60 | B7: 1 | C7: 3 | D7: 4 | E7: 2 | F7: 6 | G7: 16 | J7: 35-60 | K7: 1 | L7: 3 | M7: 4 | N7: 2 | O7: 6 | P7: 16
A8: 120+ | B8: 2 | D8: 5 | E8: 2 | F8: 2 | G8: 11 | J8: 120+ | K8: 2 | M8: 5 | N8: 2 | O8: 2 | P8: 11
A9: <35 | B9: 4 | C9: 12 | D9: 24 | E9: 32 | F9: 8 | G9: 80 | J9: <35 | K9: 4 | L9: 12 | M9: 24 | N9: 32 | O9: 8 | P9: 80
A10: Grand Total | B10: 13 | C10: 19 | D10: 48 | E10: 43 | F10: 22 | G10: 145 | J10: Grand Total | K10: 13 | L10: 19 | M10: 48 | N10: 43 | O10: 22 | P10: 145
J12: Row Labels | K12: <10 Гб | L12: 10-20 Гб | M12: 21-30 Гб | N12: 31-40 Гб | O12: 40+ Гб | P12: Grand Total
J13: <35 минут | K13: =K9/$P$10 -> 0.027586207 | L13: =L9/$P$10 -> 0.082758621 | M13: =M9/$P$10 -> 0.16551724 | N13: =N9/$P$10 -> 0.22068966 | O13: =O9/$P$10 -> 0.055172414 | P13: =P9/$P$10 -> 0.55172414
J14: 35-60 минут | K14: =K7/$P$10 -> 0.0068965517 | L14: =L7/$P$10 -> 0.020689655 | M14: =M7/$P$10 -> 0.027586207 | N14: =N7/$P$10 -> 0.013793103 | O14: =O7/$P$10 -> 0.04137931 | P14: =P7/$P$10 -> 0.11034483
J15: 61-90 минут | K15: =K6/$P$10 -> 0.013793103 | L15: =L6/$P$10 -> 0.0068965517 | M15: =M6/$P$10 -> 0.062068966 | N15: =N6/$P$10 -> 0.034482759 | O15: =O6/$P$10 -> 0.020689655 | P15: =P6/$P$10 -> 0.13793103
J16: 91-120 минут | K16: =K5/$P$10 -> 0.027586207 | L16: =L5/$P$10 -> 0.020689655 | M16: =M5/$P$10 -> 0.04137931 | N16: =N5/$P$10 -> 0.013793103 | O16: =O5/$P$10 -> 0.020689655 | P16: =P5/$P$10 -> 0.12413793
J17: 120+ минут | K17: =K8/$P$10 -> 0.013793103 | L17: =L8/$P$10 -> 0 | M17: =M8/$P$10 -> 0.034482759 | N17: =N8/$P$10 -> 0.013793103 | O17: =O8/$P$10 -> 0.013793103 | P17: =P8/$P$10 -> 0.075862069
J18: Grand Total | K18: =K10/$P$10 -> 0.089655172 | L18: =L10/$P$10 -> 0.13103448 | M18: =M10/$P$10 -> 0.33103448 | N18: =N10/$P$10 -> 0.29655172 | O18: =O10/$P$10 -> 0.15172414 | P18: =SUM(K13:O17) -> 1
R21: Лучший набор | S21: <35 минут + 31-40 ГБ
R22: Лучший набор интернета | S22: 21-30 ГБ
R23: Лучший набор минут | S23: <35 минут

Sheet Сгруппированные данные
A1: ToolKit Excel. Базовый уровень. Проект
A2: ID | B2: Возраст | C2: Принадлежность | D2: Сколько минут в неделю вы тратите на звонки? | E2: Сколько интернет трафика вы тратите в месяц с вашего мобильного устройства? | F2: Сколько вы готовы заплатить за оптимальный тариф? | G2: Сумма, которую готовы платить | H2: Нужные ГБ | I2: Нужные минуты | J2: Готов ли платить за онлайн? | K2: Оцените, насколько вы довольны своим мобильным оператором?
A3: 1 | B3: 24 | C3: Не абонент | D3: <35 | E3: <10 Гб | F3: 451-550 | G3: =IF(F3="550+ рублей",550,IF(F3="451-550",451,IF(F3="351-450",351,IF(F3="250-350",350,250)))) -> 451 | H3: =IF(E3="<10 Гб",10,IF(E3="10-20 Гб",20,IF(E3="21-30 Гб",30,IF(E3="31-40 Гб",40,41)))) -> 10 | I3: =IF(D3="<35",35,IF(D3="35-60",60,IF(D3="61-90",90,IF(D3="91-120",120,121)))) -> 35 | J3: =IF(AND(G3>330,I3<36,H3<41,OR(K3="Скорее не удовлетворен",K3="Абсолютно не уловлетворен",K3="Затрудняюсь ответить")),"Да","Нет") -> Нет | K3: Полностью удовлетворен
A4: 2 | B4: 21 | C4: Не абонент | D4: <35 | E4: <10 Гб | F4: 451-550 | G4: =IF(F4="550+ рублей",550,IF(F4="451-550",451,IF(F4="351-450",351,IF(F4="250-350",350,250)))) -> 451 | H4: =IF(E4="<10 Гб",10,IF(E4="10-20 Гб",20,IF(E4="21-30 Гб",30,IF(E4="31-40 Гб",40,41)))) -> 10 | I4: =IF(D4="<35",35,IF(D4="35-60",60,IF(D4="61-90",90,IF(D4="91-120",120,121)))) -> 35 | J4: =IF(AND(G4>330,I4<36,H4<41,OR(K4="Скорее не удовлетворен",K4="Абсолютно не уловлетворен",K4="Затрудняюсь ответить")),"Да","Нет") -> Да | K4: Затрудняюсь ответить
A5: 3 | B5: 25 | C5: Не абонент | D5: <35 | E5: 21-30 Гб | F5: 550+ рублей | G5: =IF(F5="550+ рублей",550,IF(F5="451-550",451,IF(F5="351-450",351,IF(F5="250-350",350,250)))) -> 550 | H5: =IF(E5="<10 Гб",10,IF(E5="10-20 Гб",20,IF(E5="21-30 Гб",30,IF(E5="31-40 Гб",40,41)))) -> 30 | I5: =IF(D5="<35",35,IF(D5="35-60",60,IF(D5="61-90",90,IF(D5="91-120",120,121)))) -> 35 | J5: =IF(AND(G5>330,I5<36,H5<41,OR(K5="Скорее не удовлетворен",K5="Абсолютно не уловлетворен",K5="Затрудняюсь ответить")),"Да","Нет") -> Нет | K5: Скорее удовлетворен
A6: 4 | B6: 23 | C6: Не абонент | D6: <35 | E6: 40+ Гб | F6: 550+ рублей | G6: =IF(F6="550+ рублей",550,IF(F6="451-550",451,IF(F6="351-450",351,IF(F6="250-350",350,250)))) -> 550 | H6: =IF(E6="<10 Гб",10,IF(E6="10-20 Гб",20,IF(E6="21-30 Гб",30,IF(E6="31-40 Гб",40,41)))) -> 41 | I6: =IF(D6="<35",35,IF(D6="35-60",60,IF(D6="61-90",90,IF(D6="91-120",120,121)))) -> 35 | J6: =IF(AND(G6>330,I6<36,H6<41,OR(K6="Скорее не удовлетворен",K6="Абсолютно не уловлетворен",K6="Затрудняюсь ответить")),"Да","Нет") -> Нет | K6: Скорее удовлетворен
A7: 5 | B7: 18 | C7: Не абонент | D7: <35 | E7: <10 Гб | F7: 451-550 | G7: =IF(F7="550+ рублей",550,IF(F7="451-550",451,IF(F7="351-450",351,IF(F7="250-350",350,250)))) -> 451 | H7: =IF(E7="<10 Гб",10,IF(E7="10-20 Гб",20,IF(E7="21-30 Гб",30,IF(E7="31-40 Гб",40,41)))) -> 10 | I7: =IF(D7="<35",35,IF(D7="35-60",60,IF(D7="61-90",90,IF(D7="91-120",120,121)))) -> 35 | J7: =IF(AND(G7>330,I7<36,H7<41,OR(K7="Скорее не удовлетворен",K7="Абсолютно не уловлетворен",K7="Затрудняюсь ответить")),"Да","Нет") -> Нет | K7: Полностью удовлетворен
A8: 6 | B8: 19 | C8: Не абонент | D8: <35 | E8: 40+ Гб | F8: до 250 рублей | G8: =IF(F8="550+ рублей",550,IF(F8="451-550",451,IF(F8="351-450",351,IF(F8="250-350",350,250)))) -> 250 | H8: =IF(E8="<10 Гб",10,IF(E8="10-20 Гб",20,IF(E8="21-30 Гб",30,IF(E8="31-40 Гб",40,41)))) -> 41 | I8: =IF(D8="<35",35,IF(D8="35-60",60,IF(D8="61-90",90,IF(D8="91-120",120,121)))) -> 35 | J8: =IF(AND(G8>330,I8<36,H8<41,OR(K8="Скорее не удовлетворен",K8="Абсолютно не уловлетворен",K8="Затрудняюсь ответить")),"Да","Нет") -> Нет | K8: Скорее удовлетворен
A9: 7 | B9: 21 | C9: Не абонент | D9: <35 | E9: 21-30 Гб | F9: 451-550 | G9: =IF(F9="550+ рублей",550,IF(F9="451-550",451,IF(F9="351-450",351,IF(F9="250-350",350,250)))) -> 451 | H9: =IF(E9="<10 Гб",10,IF(E9="10-20 Гб",20,IF(E9="21-30 Гб",30,IF(E9="31-40 Гб",40,41)))) -> 30 | I9: =IF(D9="<35",35,IF(D9="35-60",60,IF(D9="61-90",90,IF(D9="91-120",120,121)))) -> 35 | J9: =IF(AND(G9>330,I9<36,H9<41,OR(K9="Скорее не удовлетворен",K9="Абсолютно не уловлетворен",K9="Затрудняюсь ответить")),"Да","Нет") -> Да | K9: Скорее не удовлетворен
A10: 8 | B10: 24 | C10: Не абонент | D10: <35 | E10: 31-40 Гб | F10: 250-350 | G10: =IF(F10="550+ рублей",550,IF(F10="451-550",451,IF(F10="351-450",351,IF(F10="250-350",350,250)))) -> 350 | H10: =IF(E10="<10 Гб",10,IF(E10="10-20 Гб",20,IF(E10="21-30 Гб",30,IF(E10="31-40 Гб",40,41)))) -> 40 | I10: =IF(D10="<35",35,IF(D10="35-60",60,IF(D10="61-90",90,IF(D10="91-120",120,121)))) -> 35 | J10: =IF(AND(G10>330,I10<36,H10<41,OR(K10="Скорее не удовлетворен",K10="Абсолютно не уловлетворен",K10="Затрудняюсь ответить")),"Да","Нет") -> Нет | K10: Скорее удовлетворен
A11: 9 | B11: 21 | C11: Не абонент | D11: <35 | E11: 10-20 Гб | F11: 250-350 | G11: =IF(F11="550+ рублей",550,IF(F11="451-550",451,IF(F11="351-450",351,IF(F11="250-350",350,250)))) -> 350 | H11: =IF(E11="<10 Гб",10,IF(E11="10-20 Гб",20,IF(E11="21-30 Гб",30,IF(E11="31-40 Гб",40,41)))) -> 20 | I11: =IF(D11="<35",35,IF(D11="35-60",60,IF(D11="61-90",90,IF(D11="91-120",120,121)))) -> 35 | J11: =IF(AND(G11>330,I11<36,H11<41,OR(K11="Скорее не удовлетворен",K11="Абсолютно не уловлетворен",K11="Затрудняюсь ответить")),"Да","Нет") -> Да | K11: Скорее не удовлетворен
A12: 10 | B12: 22 | C12: Не абонент | D12: <35 | E12: 10-20 Гб | F12: 250-350 | G12: =IF(F12="550+ рублей",550,IF(F12="451-550",451,IF(F12="351-450",351,IF(F12="250-350",350,250)))) -> 350 | H12: =IF(E12="<10 Гб",10,IF(E12="10-20 Гб",20,IF(E12="21-30 Гб",30,IF(E12="31-40 Гб",40,41)))) -> 20 | I12: =IF(D12="<35",35,IF(D12="35-60",60,IF(D12="61-90",90,IF(D12="91-120",120,121)))) -> 35 | J12: =IF(AND(G12>330,I12<36,H12<41,OR(K12="Скорее не удовлетворен",K12="Абсолютно не уловлетворен",K12="Затрудняюсь ответить")),"Да","Нет") -> Да | K12: Затрудняюсь ответить
A13: 11 | B13: 18 | C13: Не абонент | D13: 91-120 | E13: 21-30 Гб | F13: 550+ рублей | G13: =IF(F13="550+ рублей",550,IF(F13="451-550",451,IF(F13="351-450",351,IF(F13="250-350",350,250)))) -> 550 | H13: =IF(E13="<10 Гб",10,IF(E13="10-20 Гб",20,IF(E13="21-30 Гб",30,IF(E13="31-40 Гб",40,41)))) -> 30 | I13: =IF(D13="<35",35,IF(D13="35-60",60,IF(D13="61-90",90,IF(D13="91-120",120,121)))) -> 120 | J13: =IF(AND(G13>330,I13<36,H13<41,OR(K13="Скорее не удовлетворен",K13="Абсолютно не уловлетворен",K13="Затрудняюсь ответить")),"Да","Нет") -> Нет | K13: Затрудняюсь ответить
A14: 12 | B14: 18 | C14: Не абонент | D14: 61-90 | E14: 21-30 Гб | F14: до 250 рублей | G14: =IF(F14="550+ рублей",550,IF(F14="451-550",451,IF(F14="351-450",351,IF(F14="250-350",350,250)))) -> 250 | H14: =IF(E14="<10 Гб",10,IF(E14="10-20 Гб",20,IF(E14="21-30 Гб",30,IF(E14="31-40 Гб",40,41)))) -> 30 | I14: =IF(D14="<35",35,IF(D14="35-60",60,IF(D14="61-90",90,IF(D14="91-120",120,121)))) -> 90 | J14: =IF(AND(G14>330,I14<36,H14<41,OR(K14="Скорее не удовлетворен",K14="Абсолютно не уловлетворен",K14="Затрудняюсь ответить")),"Да","Нет") -> Нет | K14: Затрудняюсь ответить
... A299: 304 | B299: 20 | C299: Не абонент | D299: 35-60 | E299: 21-30 Гб | F299: 250-350 | G299: =IF(F299="550+ рублей",550,IF(F299="451-550",451,IF(F299="351-450",351,IF(F299="250-350",350,250)))) -> 350 | H299: =IF(E299="<10 Гб",10,IF(E299="10-20 Гб",20,IF(E299="21-30 Гб",30,IF(E299="31-40 Гб",40,41)))) -> 30 | I299: =IF(D299="<35",35,IF(D299="35-60",60,IF(D299="61-90",90,IF(D299="91-120",120,121)))) -> 60 | J299: =IF(AND(G299>330,I299<36,H299<41,OR(K299="Скорее не удовлетворен",K299="Абсолютно не уловлетворен",K299="Затрудняюсь ответить")),"Да","Нет") -> Нет | K299: Затрудняюсь ответить
A300: AXOBV991 | B300: 18 | C300: Абонент | D300: 91-120 | E300: 40+ Гб | F300: =VLOOKUP(VLOOKUP(A300,'Личные данные'!A:V,6,0),'Личные данные'!$X$17:$AA$21,2,0) -> 770
A301: YIWQU824 | B301: 18 | C301: Абонент | D301: <35 | E301: 31-40 Гб | F301: =VLOOKUP(VLOOKUP(A301,'Личные данные'!A:V,6,0),'Личные данные'!$X$17:$AA$21,2,0) -> 330
A302: TVVXJ702 | B302: 18 | C302: Абонент | D302: <35 | E302: 31-40 Гб | F302: =VLOOKUP(VLOOKUP(A302,'Личные данные'!A:V,6,0),'Личные данные'!$X$17:$AA$21,2,0) -> 330
A303: YIZKW418 | B303: 18 | C303: Абонент | D303: <35 | E303: <10 Гб | F303: =VLOOKUP(VLOOKUP(A303,'Личные данные'!A:V,6,0),'Личные данные'!$X$17:$AA$21,2,0) -> 220
A304: MXYOM801 | B304: 18 | C304: Абонент | D304: <35 | E304: 31-40 Гб | F304: =VLOOKUP(VLOOKUP(A304,'Личные данные'!A:V,6,0),'Личные данные'!$X$17:$AA$21,2,0) -> 330
A305: GVTCR352 | B305: 18 | C305: Абонент | D305: 61-90 | E305: 21-30 Гб | F305: =VLOOKUP(VLOOKUP(A305,'Личные данные'!A:V,6,0),'Личные данные'!$X$17:$AA$21,2,0) -> 440
A306: LAXMN110 | B306: 18 | C306: Абонент | D306: <35 | E306: 31-40 Гб | F306: =VLOOKUP(VLOOKUP(A306,'Личные данные'!A:V,6,0),'Личные данные'!$X$17:$AA$21,2,0) -> 330
A307: PUAAG520 | B307: 18 | C307: Абонент | D307: <35 | E307: 21-30 Гб | F307: =VLOOKUP(VLOOKUP(A307,'Личные данные'!A:V,6,0),'Личные данные'!$X$17:$AA$21,2,0) -> 440
A308: FBCVN966 | B308: 18 | C308: Абонент | D308: 91-120 | E308: 31-40 Гб | F308: =VLOOKUP(VLOOKUP(A308,'Личные данные'!A:V,6,0),'Личные данные'!$X$17:$AA$21,2,0) -> 550
A309: EMVOF074 | B309: 18 | C309: Абонент | D309: 91-120 | E309: 21-30 Гб | F309: =VLOOKUP(VLOOKUP(A309,'Личные данные'!A:V,6,0),'Личные данные'!$X$17:$AA$21,2,0) -> 550
A310: FRRVI702 | B310: 18 | C310: Абонент | D310: <35 | E310: 31-40 Гб | F310: =VLOOKUP(VLOOKUP(A310,'Личные данные'!A:V,6,0),'Личные данные'!$X$17:$AA$21,2,0) -> 550
A311: NRQRT304 | B311: 18 | C311: Абонент | D311: <35 | E311: 31-40 Гб | F311: =VLOOKUP(VLOOKUP(A311,'Личные данные'!A:V,6,0),'Личные данные'!$X$17:$AA$21,2,0) -> 330
... A1438: DIWQR122 | B1438: 25 | C1438: Абонент | D1438: 91-120 | E1438: 10-20 Гб | F1438: =VLOOKUP(VLOOKUP(A1438,'Личные данные'!A:V,6,0),'Личные данные'!$X$17:$AA$21,2,0) -> 550

Sheet Свод (Сгруп. дан.)
A3: Count of ID | B3: Сколько интернет трафика вы тратите в месяц с вашего мобильного устройства?
A4: Сколько минут в неделю/Гб в месяц вы тратите? | B4: <10 Гб | C4: 10-20 Гб | D4: 21-30 Гб | E4: 31-40 Гб | F4: 40+ Гб | G4: Grand Total
A5: <35 | B5: 0.088440111 | C5: 0.054317549 | D5: 0.12674095 | E5: 0.25069638 | F5: 0.026462396 | G5: 0.54665738
A6: 120+ | B6: 0.0069637883 | C6: 0.0069637883 | D6: 0.01183844 | E6: 0.011142061 | F6: 0.020194986 | G6: 0.057103064
A7: 35-60 | B7: 0.034818942 | C7: 0.018802228 | D7: 0.056406685 | E7: 0.017409471 | F7: 0.010445682 | G7: 0.13788301
A8: 61-90 | B8: 0.021587744 | C8: 0.027158774 | D8: 0.068245125 | E8: 0.024373259 | F8: 0.0048746518 | G8: 0.14623955
A9: 91-120 | B9: 0.017409471 | C9: 0.015320334 | D9: 0.046657382 | E9: 0.025766017 | F9: 0.0069637883 | G9: 0.11211699
A10: Grand Total | B10: 0.16922006 | C10: 0.12256267 | D10: 0.30988858 | E10: 0.32938719 | F10: 0.068941504 | G10: 1

Sheet Свод (Тариф)
A1: Принадлежность | B1: Не абонент
A2: Сколько минут в неделю вы тратите на звонки? | B2: <35
A3: Сколько интернет трафика вы тратите в месяц с вашего мобильного устройства? | B3: (Multiple Items) | H3: Сколько вы готовы заплатить за оптимальный тариф? | I3: Количество
A4: Оцените, насколько вы довольны своим мобильным оператором? | B4: (Multiple Items) | H4: 220 | I4: 81
H5: 330 | I5: 413
A6: Row Labels | B6: Count of ID | H6: 440 | I6: 369
A7: до 250 рублей | B7: 0.26388889 | H7: 550 | I7: 219
A8: 250-350 | B8: 0.30555556 | H8: 770 | I8: 57
A9: 351-450 | B9: 0.16666667
A10: 451-550 | B10: 0.18055556 | H10: Сколько вы готовы заплатить за оптимальный тариф? | I10: Количество
A11: 550+ рублей | B11: 0.083333333 | H11: 250-350 | I11: 104
A12: Grand Total | B12: 1 | H12: 351-450 | I12: 45
H13: 451-550 | I13: 31
H14: 550+ рублей | I14: 36
H15: до 250 рублей | I15: 81

Sheet Матрица
C4: Доп услуги | D4: Подписка на онлайн-кинотеатр | E4: Подписка на электронную библиотеку | F4: Подписка на TV | G4: Подписка на онлайн-курсы | H4: Фитнес приложение | I4: Итог
C5: Подписка на онлайн-кинотеатр | D5: =IF(D$4=$C5,0,COUNTIFS('Личные данные'!K:K,"=1",'Личные данные'!$K:$K,"=1"))/$K$12 -> 0 | E5: =IF(E$4=$C5,0,COUNTIFS('Личные данные'!L:L,"=1",'Личные данные'!$K:$K,"=1"))/$K$12 -> 0.11877395 | F5: =IF(F$4=$C5,0,COUNTIFS('Личные данные'!M:M,"=1",'Личные данные'!$K:$K,"=1"))/$K$12 -> 0.038314176 | G5: =IF(G$4=$C5,0,COUNTIFS('Личные данные'!N:N,"=1",'Личные данные'!$K:$K,"=1"))/$K$12 -> 0.030651341 | H5: =IF(H$4=$C5,0,COUNTIFS('Личные данные'!O:O,"=1",'Личные данные'!$K:$K,"=1"))/$K$12 -> 0.11685824 | I5: =SUM(D5:H5) -> 0.3045977
C6: Подписка на электронную библиотеку | D6: =IF(D$4=$C6,0,COUNTIFS('Личные данные'!K:K,"=1",'Личные данные'!$L:$L,"=1"))/$K$12 -> 0.11877395 | E6: =IF(E$4=$C6,0,COUNTIFS('Личные данные'!L:L,"=1",'Личные данные'!$L:$L,"=1"))/$K$12 -> 0 | F6: =IF(F$4=$C6,0,COUNTIFS('Личные данные'!M:M,"=1",'Личные данные'!$L:$L,"=1"))/$K$12 -> 0.030651341 | G6: =IF(G$4=$C6,0,COUNTIFS('Личные данные'!N:N,"=1",'Личные данные'!$L:$L,"=1"))/$K$12 -> 0.049808429 | H6: =IF(H$4=$C6,0,COUNTIFS('Личные данные'!O:O,"=1",'Личные данные'!$L:$L,"=1"))/$K$12 -> 0.070881226 | I6: =SUM(D6:H6) -> 0.27011494
C7: Подписка на TV | D7: =IF(D$4=$C7,0,COUNTIFS('Личные данные'!K:K,"=1",'Личные данные'!$M:$M,"=1"))/$K$12 -> 0.038314176 | E7: =IF(E$4=$C7,0,COUNTIFS('Личные данные'!L:L,"=1",'Личные данные'!$M:$M,"=1"))/$K$12 -> 0.030651341 | F7: =IF(F$4=$C7,0,COUNTIFS('Личные данные'!M:M,"=1",'Личные данные'!$M:$M,"=1"))/$K$12 -> 0 | G7: =IF(G$4=$C7,0,COUNTIFS('Личные данные'!N:N,"=1",'Личные данные'!$M:$M,"=1"))/$K$12 -> 0.011494253 | H7: =IF(H$4=$C7,0,COUNTIFS('Личные данные'!O:O,"=1",'Личные данные'!$M:$M,"=1"))/$K$12 -> 0.021072797 | I7: =SUM(D7:H7) -> 0.10153257
C8: Подписка на онлайн-курсы | D8: =IF(D$4=$C8,0,COUNTIFS('Личные данные'!K:K,"=1",'Личные данные'!$N:$N,"=1"))/$K$12 -> 0.030651341 | E8: =IF(E$4=$C8,0,COUNTIFS('Личные данные'!L:L,"=1",'Личные данные'!$N:$N,"=1"))/$K$12 -> 0.049808429 | F8: =IF(F$4=$C8,0,COUNTIFS('Личные данные'!M:M,"=1",'Личные данные'!$N:$N,"=1"))/$K$12 -> 0.011494253 | G8: =IF(G$4=$C8,0,COUNTIFS('Личные данные'!N:N,"=1",'Личные данные'!$N:$N,"=1"))/$K$12 -> 0 | H8: =IF(H$4=$C8,0,COUNTIFS('Личные данные'!O:O,"=1",'Личные данные'!$N:$N,"=1"))/$K$12 -> 0.011494253 | I8: =SUM(D8:H8) -> 0.10344828
C9: Фитнес приложение | D9: =IF(D$4=$C9,0,COUNTIFS('Личные данные'!K:K,"=1",'Личные данные'!$O:$O,"=1"))/$K$12 -> 0.11685824 | E9: =IF(E$4=$C9,0,COUNTIFS('Личные данные'!L:L,"=1",'Личные данные'!$O:$O,"=1"))/$K$12 -> 0.070881226 | F9: =IF(F$4=$C9,0,COUNTIFS('Личные данные'!M:M,"=1",'Личные данные'!$O:$O,"=1"))/$K$12 -> 0.021072797 | G9: =IF(G$4=$C9,0,COUNTIFS('Личные данные'!N:N,"=1",'Личные данные'!$O:$O,"=1"))/$K$12 -> 0.011494253 | H9: =IF(H$4=$C9,0,COUNTIFS('Личные данные'!O:O,"=1",'Личные данные'!$O:$O,"=1"))/$K$12 -> 0 | I9: =SUM(D9:H9) -> 0.22030651
C10: Итог | D10: =SUM(D5:D9) -> 0.3045977 | E10: =SUM(E5:E9) -> 0.27011494 | F10: =SUM(F5:F9) -> 0.10153257 | G10: =SUM(G5:G9) -> 0.10344828 | H10: =SUM(H5:H9) -> 0.22030651 | I10: =SUM(D10:H10) -> 1
K12: 522

Sheet Дополнительные данные
A1: ToolKit Excel. Базовый уровень. Проект
A3: Тарифные планы | F3: Дополнительные услуги
A4: Тариф | B4: Абонентская плата | C4: Звонки | D4: Гб | F4: Подписка на онлайн-кинотеатр
A5: Ультра | B5: 770 | C5: 700 | D5: 50 | F5: Подписка на электронную библиотеку
A6: Премиум | B6: 550 | C6: 500 | D6: 35 | F6: Подписка на TV
A7: Комфорт | B7: 440 | C7: 400 | D7: 30 | F7: Подписка на онлайн-курсы
A8: Онлайн | B8: 330 | C8: 150 | D8: 40 | F8: Фитнес приложение
A9: Базовый | B9: 220 | C9: 200 | D9: 5
A11: Вопросы анкеты
A13: 1. Оцените, насколько вы удолетворены своим сотовым оператором.
A14: Абсолютно не удовлетворен
A15: Скорее не удовлетворен
A16: Затрудняюсь ответить
A17: Скорее удовлетворен
A18: Полностью удовлетворен
A20: 2. Сколько минут в неделю вы тратите на звонки?
A21: до 35 минут
A22: 35-60 минут
A23: 61-90 минут
A24: 91-120 минут
... A39: более 550 рублей
